# [\#648 Issue](https://github.com/ethereum/solidity/issues/648) `closed`: CALL always returns true

#### <img src="https://avatars.githubusercontent.com/u/6198746?v=4" width="50">[lastperson](https://github.com/lastperson) opened issue at [2016-06-14 11:47](https://github.com/ethereum/solidity/issues/648):

Hello. Please consider following example:

``` js
contract Exceptional {
    function forward(uint left) returns(bool) {
        if (left == 0) {
            return true;
        }
        return address(this).call(0x4fa679d8, left-1);
    }
}
```

This function always results in `true`. According to https://github.com/ethereum/wiki/wiki/Solidity-Features#detect-failed-calls it should return `false` if stack depth limit hit (when we call `forward(1025)`).
Am I missing something, or is this really a bug?
Using solidity-browser with 0.3.5-0.

Is it impossible to `throw` in case of stack depth limit?


#### <img src="https://avatars.githubusercontent.com/u/6198746?v=4" width="50">[lastperson](https://github.com/lastperson) commented at [2016-06-14 14:40](https://github.com/ethereum/solidity/issues/648#issuecomment-225903337):

Found the problem in my logic. The last call that is beyond stack depth will in fact return `false`. Will open another issue regarding throwing instead of STOP.


-------------------------------------------------------------------------------



[Export of Github issue for [ethereum/solidity](https://github.com/ethereum/solidity). Generated on 2024.12.15 at 06:45:24.]
